Workbook
Name _año_: #REF!
Name _ArGypBanMin_: #REF!
Name _ArGypNr_: #REF!
Name _mes_: #REF!
Name _RutGyp_: #REF!
Name Activos: #REF!
Name año: #REF!
Name cedes: #REF!
Name Contratación: #REF!
Name Datos: #REF!
Name DiasCategorias: #REF!
Name Gasto_Ppto_Acum: #REF!
Name Gasto_Real_Acum: #REF!
Name indicadores: #REF!
Name Matriculas: #REF!
Name MES: #REF!
Name PPP: OFFSET(#REF!,1,,,(COUNTA(#REF!)-(COUNTIF(#REF!,""))))
Name Procedencia: #REF!
Name Proceso: #REF!
Name Renuncia: #REF!
Name rewr: #REF!
Name roles: #REF!
Name TablaInventario: #REF!
Name Tipoperfil: #REF!

Sheet Hoja4
K1: =+K3+16 -> 1047 | L1: =+L3+16 -> 1019 | O1: =+N3-Q3 -> 20 | P1: ASESORES | Q1: =+N2-Q2 -> 23 | R1: =+R3-18 -> 1003 | T1: ASESORES | V1: =+R3-V3 -> 23.304126 | Z1: ASESORES | AF1: ASESORES | AL1: ASESORES | AR1: ASESORES
B2: =+B19+B42 -> 858 | C2: =+C19+C42 -> 846 | D2: =+D19+D42 -> 836 | E2: =+E19+E42 -> 878 | F2: =+F19+F42 -> 854 | K2: =+K19+K42 -> 879 | L2: =+L19+L42 -> 858 | N2: =+N19+N42 -> 847 | O2: =+O19+O42 -> 824 | Q2: =+Q19+Q42 -> 824 | R2: =+R19+R42 -> 837 | S2: =+S19+S42 -> 832 | T2: =+T19+T42 -> 889 | X2: =+X19+X42 -> 832.4755 | Z2: =+Z19+Z42 -> 851 | AB2: =+AB19+AB42 -> 804.33005 | AD2: =+AD19+AD42 -> 823.93005 | AE2: =+AE19+AE42 -> 0 | AF2: =+AF19+AF42 -> 784 | AJ2: =+AJ19+AJ42 -> 829 | AK2: =+AK19+AK42 -> 0 | AL2: =+AL19+AL42 -> 761 | AM2: =+AJ2/AL2 -> 1.0893561 | AN2: =+AN19+AN42 -> 819.27767 | AP2: =+AP19+AP42 -> 837 | AQ2: =+AQ19+AQ42 -> 0 | AR2: =+AR19+AR42 -> 732 | AS2: =+AP2/AR2 -> 1.1434426 | AT2: =+AT19+AT42 -> 831.67693
B3: =B19+B42+B49 -> 1028 | C3: =C19+C42+C49 -> 1008 | D3: =D19+D42+D49 -> 1007 | E3: =E19+E42+E49 -> 1038 | F3: =F19+F42+F49 -> 1008 | G3: =G19+G42+G49 -> 1007 | H3: =H19+H42+H49 -> 1034 | I3: =I19+I42+I49 -> 1022 | ... O3: =O19+O42+O49 -> 983 | P3: =+P10+P19+P42+P49 -> 1007 | Q3: =+Q19+Q42+Q49 -> 986 | R3: =R19+R42+R49 -> 1021 | S3: =S19+S42+S49 -> 1015 | T3: =T19+T42+T49 -> 1116 | U3: =R3/T3 -> 0.91487455 | V3: =V19+V42+V49 -> 997.69587 | X3: =X19+X42+X49 -> 1026.4359 | Z3: =Z19+Z42+Z49 -> 1096 | AA3: =X3/Z3 -> 0.93652908 | AB3: =AB19+AB42+AB49 -> 984.79043 | AD3: =AD19+AD42+AD49 -> 1021.4904 | AF3: =AF19+AF42+AF49 -> 1026 | AG3: =AD3/AF3 -> 0.9956047 | AH3: =AH19+AH42+AH49 -> 950.53295 | AJ3: =ROUNDDOWN(AJ19+AJ42+AJ49,0) -> 1048 | AL3: =AL19+AL42+AL49 -> 1016 | AM3: =AJ3/AL3 -> 1.0314961 | AP3: =ROUNDDOWN(AP19+AP42+AP49,0) -> 1074 | AR3: =AR19+AR42+AR49 -> 972 | AS3: =AP3/AR3 -> 1.1049383
A4: LÍNEA | B4: INI-ENE | C4: REAL-ENE | D4: CAPACITY | E4: INI-FEB | F4: REAL-FEB | G4: CAPACITY | H4: INI-MAR | I4: REAL-MAR | J4: CAPACITY | K4: INI-ABR | L4: REAL-ABR | M4: CAPACITY | N4: INI-MAY | O4: REAL-MAY | P4: CAPACITY | Q4: CIERRE | R4: INI-JUN | S4: REAL-JUN | T4: CAPACITY | U4: %COB | V4: FORECAST CIERRE | W4: CIERRE | X4: INI-JUL | Y4: REAL-JUL | Z4: CAPACITY | AA4: %COB | AB4: FORECAST CIERRE | AC4: CIERRE | AD4: INI-AGO | AE4: REAL-JUN | AF4: CAPACITY | AG4: %COB | AH4: FORECAST CIERRE | AI4: CIERRE | AJ4: INI-SEP | AK4: REAL-JUN | AL4: CAPACITY | AM4: %COB | AN4: FORECAST CIERRE | AO4: CIERRE | AP4: INI-OCT | AQ4: REAL-JUN | AR4: CAPACITY | AS4: %COB | AT4: FORECAST CIERRE
A5: FORMATIVO INBOUND
A6: TRAINEE M2 | B6: 35 | C6: 32 | E6: 40 | F6: 40 | H6: 40 | I6: 39 | K6: 16 | L6: 16 | N6: 21 | O6: 19 | Q6: 19 | R6: 22 | S6: 22 | U6: =+IFERROR(R6/T6,"") | V6: =+Hoja2!G4 -> 20.24 | X6: =+V7 -> 29.4 | AA6: =+IFERROR(X6/Z6,"") | AB6: =+Hoja2!K4 -> 27.048 | AD6: =+AB7 -> 19.6 | AE6: =AC6 -> 0 | AF6: =+_xlfn.XLOOKUP(A6,'[3]REQUERIMIENTO INBOUND'!B:B,'[3]REQUERIMIENTO INBOUND'!AE:AE,"",0) | AG6: =+IFERROR(AD6/AF6,"") | AH6: =+(AD6)*0.9 -> 17.64 | AJ6: =+AH7 -> 19.6 | AL6: =+_xlfn.XLOOKUP(A6,'[3]REQUERIMIENTO INBOUND'!B:B,'[3]REQUERIMIENTO INBOUND'!AI:AI,"",0) | AM6: =+IFERROR(AJ6/AL6,"") | AN6: =+(AJ6)*0.9 -> 17.64 | AP6: =+AN7 -> 19.6 | AR6: =+_xlfn.XLOOKUP(H6,'[3]REQUERIMIENTO INBOUND'!I:I,'[3]REQUERIMIENTO INBOUND'!AP:AP,"",0) | AS6: =+IFERROR(AP6/AR6,"") | AT6: =+(AP6)*0.9 -> 17.64
A7: TRAINEE M1 | B7: 41 | C7: 41 | E7: 43 | F7: 43 | H7: 30 | I7: 30 | K7: 22 | L7: 21 | N7: 25 | O7: 22 | Q7: 22 | R7: 30 | S7: 30 | V7: =+Hoja2!G3 -> 29.4 | X7: 20 | AB7: =+Hoja2!K3 -> 19.6 | AD7: 20 | AH7: =+(AD7)*0.98 -> 19.6 | AJ7: 20 | AN7: =+(AJ7)*0.98 -> 19.6 | AP7: 20 | AT7: =+(AP7)*0.98 -> 19.6
A8: CW M2 | E8: 11 | F8: 9 | K8: 16 | L8: 16 | N8: 30 | O8: 30 | Q8: 30 | R8: 15 | S8: 15 | V8: =+R8*0.9 -> 13.5 | X8: =+V9 -> 19 | AB8: =+X8*0.9 -> 17.1 | AD8: =+AB9 -> 34 | AH8: =+AD8*0.9 -> 30.6 | AJ8: =+AH9 -> 34 | AN8: =+AJ8*0.9 -> 30.6 | AP8: =+AN9 -> 34 | AT8: =+AP8*0.9 -> 30.6
A9: CW M1 | B9: 11 | C9: 11 | H9: 16 | I9: 16 | K9: 30 | L9: 30 | N9: 13 | O9: 13 | Q9: 13 | R9: 20 | S9: 20 | V9: 19 | X9: 35 | AB9: =X9-1 -> 34 | AD9: 35 | AH9: =+AD9-1 -> 34 | AJ9: 35 | AN9: =+AJ9-1 -> 34 | AP9: 35 | AT9: =+AP9-1 -> 34
A10: TOTAL | B10: =+SUM(B6:B9) -> 87 | C10: =+SUM(C6:C9) -> 84 | E10: =+SUM(E6:E9) -> 94 | F10: =+SUM(F6:F9) -> 92 | H10: =+SUM(H6:H9) -> 86 | I10: =+SUM(I6:I9) -> 85 | K10: =+SUM(K6:K9) -> 84 | L10: =+SUM(L6:L9) -> 83 | N10: =+SUM(N6:N9) -> 89 | O10: =+SUM(O6:O9) -> 84 | Q10: =+SUM(Q6:Q9) -> 84 | R10: 87 | S10: 87 | T10: =+SUM(T6:T9) -> 0 | U10: =+SUM(U16) -> 0.59055118 | V10: =+SUM(V5:V9) -> 82.14 | X10: =+SUM(X6:X9) -> 103.4 | Y10: =+SUM(Y6:Y9) -> 0 | Z10: =+SUM(Z6:Z9) -> 0 | AA10: =+SUM(AA16) -> 0.54345455 | AB10: =+SUM(AB6:AB9) -> 97.748 | AD10: =+SUM(AD6:AD9) -> 108.6 | AE10: =+SUM(AE6:AE9) -> 0 | AF10: =+SUM(AF6:AF9) -> 0 | AG10: =+SUM(AG16) -> 0.56815426 | AH10: =+SUM(AH6:AH9) -> 101.84 | AJ10: =+SUM(AJ6:AJ9) -> 108.6 | AK10: =+SUM(AK6:AK9) -> 0 | AL10: =+SUM(AL6:AL9) -> 0 | AM10: =+SUM(AM5:AM9) -> 0 | AN10: =+SUM(AN6:AN9) -> 101.84 | AP10: =+SUM(AP6:AP9) -> 108.6 | AQ10: =+SUM(AQ6:AQ9) -> 0 | AR10: =+SUM(AR6:AR9) -> 0 | AS10: =+SUM(AS5:AS9) -> 0 | AT10: =+SUM(AT6:AT9) -> 101.84
A12: LÍNEA | B12: INI-ENE | C12: REAL-ENE | D12: CAPACITY | E12: INI-FEB | F12: REAL-FEB | G12: CAPACITY | H12: INI-MAR | I12: REAL-MAR | J12: CAPACITY | K12: INI-ABR | L12: REAL-ABR | M12: CAPACITY | N12: INI-MAY | O12: REAL-MAY | P12: CAPACITY | Q12: CIERRE | R12: INI-JUN | S12: REAL-JUN | T12: CAPACITY | U12: %COB | V12: FORECAST CIERRE | W12: CIERRE | X12: =+X4 -> INI-JUL | Y12: =+Y4 -> REAL-JUL | Z12: CAPACITY | AA12: %COB | AB12: FORECAST CIERRE | AC12: CIERRE | AD12: =+AD4 -> INI-AGO | AE12: REAL-JUN | AF12: CAPACITY | AG12: %COB | AH12: FORECAST CIERRE | AI12: CIERRE | AJ12: =+AJ4 -> INI-SEP | AK12: REAL-JUN | AL12: CAPACITY | AM12: %COB | AN12: FORECAST CIERRE | AO12: CIERRE | AP12: =+AP4 -> INI-OCT | AQ12: REAL-JUN | AR12: CAPACITY | AS12: %COB | AT12: FORECAST CIERRE
A13: SUSANA
A14: CONSULTAS GENERALES | B14: 292 | C14: 288 | D14: 317 | E14: 298 | F14: 287 | G14: =+'[4]Requerimiento Inbound'!$FF$4 -> 317 | H14: 272 | I14: 270 | J14: =+'[4]Requerimiento Inbound'!$FF$4 -> 317 | K14: 280 | L14: 267 | M14: =+'[4]Requerimiento Inbound'!$FF$4 -> 317 | N14: 287 | O14: 276 | P14: 317 | Q14: 276 | R14: 300 | S14: 299 | T14: 303 | U14: =+IFERROR(R14/T14,"") -> 0.99009901 | V14: =+R14*(1-[1]TASA_ROTACION!L82) -> 285.95491 | X14: =+V14+V17 -> 321.05491 | Z14: 280 | AA14: =+IFERROR(X14/Z14,"") -> 1.1466247 | AB14: =+X14*(1-[1]TASA_ROTACION!N82) -> 302.16856 | AD14: =+AB14+AB17 -> 322.19356 | AF14: =+_xlfn.XLOOKUP(A14,'[3]REQUERIMIENTO INBOUND'!B:B,'[3]REQUERIMIENTO INBOUND'!AE:AE,"",0) -> 238 | AG14: =+IFERROR(AD14/AF14,"") -> 1.3537544 | AH14: =+AD14*(1-[1]TASA_ROTACION!P82) -> 307.45133 | AJ14: =+AH14+AH17 -> 318.83852 | AL14: =+_xlfn.XLOOKUP(A14,'[3]REQUERIMIENTO INBOUND'!B:B,'[3]REQUERIMIENTO INBOUND'!AI:AI,"",0) -> 221 | AM14: =+IFERROR(AJ14/AL14,"") -> 1.4427083 | AN14: =+AJ14*(1-[1]TASA_ROTACION!AG82) -> 318.83852 | AP14: =+AN14+AN17 -> 329.22549 | AR14: =+[2]Capacity!$AM$13 -> 196 | AS14: =+IFERROR(AP14/AR14,"") -> 1.6797219 | AT14: =+AP14*(1-[1]TASA_ROTACION!AN82) -> 329.22549
A15: SWAT | B15: 21 | C15: 21 | D15: 21 | E15: 21 | F15: 21 | G15: =+'[4]Requerimiento Inbound'!$FF$24 -> 21 | H15: 22 | I15: 22 | J15: =+'[4]Requerimiento Inbound'!$FF$24 -> 21 | K15: 22 | L15: 21 | M15: =+'[4]Requerimiento Inbound'!$FF$24 -> 21 | N15: 21 | O15: 20 | P15: 21 | Q15: 20 | R15: 21 | S15: 21 | T15: 21 | U15: =+IFERROR(R15/T15,"") -> 1 | V15: 20 | X15: =+V15 -> 20 | Z15: 21 | AA15: =+IFERROR(X15/Z15,"") -> 0.95238095 | AB15: 20 | AD15: =+AB15 -> 20 | AF15: =+_xlfn.XLOOKUP(A15,'[3]REQUERIMIENTO INBOUND'!B:B,'[3]REQUERIMIENTO INBOUND'!AE:AE,"",0) -> 21 | AG15: =+IFERROR(AD15/AF15,"") -> 0.95238095 | AH15: 20 | AJ15: =+AH15 -> 20 | AL15: =+_xlfn.XLOOKUP(A15,'[3]REQUERIMIENTO INBOUND'!B:B,'[3]REQUERIMIENTO INBOUND'!AI:AI,"",0) -> 21 | AM15: =+IFERROR(AJ15/AL15,"") -> 0.95238095 | AN15: 20 | AP15: =+AN15 -> 20 | AR15: =+[2]Capacity!$AM$14 -> 21 | AS15: =+IFERROR(AP15/AR15,"") -> 0.95238095 | AT15: 20
A16: TRAINEE LLAMADAS | B16: 50 | C16: 50 | D16: 91 | E16: 66 | F16: 61 | G16: =+'[4]Requerimiento Inbound'!$FF$5 -> 91 | H16: 80 | I16: 79 | J16: =+'[4]Requerimiento Inbound'!$FF$5 -> 91 | K16: 68 | L16: 67 | M16: =+'[4]Requerimiento Inbound'!$FF$5 -> 91 | N16: 62 | O16: 57 | P16: 91 | Q16: 57 | R16: 43 | S16: 43 | T16: 127 | U16: =+(R16+R17)/T16 -> 0.59055118 | V16: =+Hoja2!G5+Hoja2!G6 -> 39.54 | X16: =+V16-X17+V6 -> 37.53 | Z16: 110 | AA16: =+IFERROR((X16+X17)/Z16,"") -> 0.54345455 | AB16: =+Hoja2!K5+Hoja2!K6 -> 33.8065 | AD16: =+AB16+AB7-AD17 -> 38.0184 | AF16: =+_xlfn.XLOOKUP(A16,'[3]REQUERIMIENTO INBOUND'!B:B,'[3]REQUERIMIENTO INBOUND'!AE:AE,"",0) -> 94 | AG16: =+IFERROR((AD16+AD17)/AF16,"") -> 0.56815426 | AH16: =+AD16*(1-[1]TASA_ROTACION!Z93) -> 38.0184 | AJ16: =+AH16+AH6-AJ17 -> 41.80911 | AL16: =+_xlfn.XLOOKUP(A16,'[3]REQUERIMIENTO INBOUND'!B:B,'[3]REQUERIMIENTO INBOUND'!AI:AI,"",0) -> 85 | AM16: =+IFERROR((AJ16+AJ17)/AL16,"") -> 0.65480471 | AN16: =+AJ16*(1-[1]TASA_ROTACION!AG93) -> 41.80911 | AP16: =+AN16+AN6-AP17 -> 46.984749 | AR16: =+[2]Capacity!$AM$11 -> 77 | AS16: =+IFERROR((AP16+AP17)/AR16,"") -> 0.77206636 | AT16: =+AP16*(1-[1]TASA_ROTACION!AN93) -> 46.984749
A17: TRAINEE-CCGG | B17: 68 | C17: 62 | E17: 37 | F17: 34 | H17: 30 | I17: 26 | K17: 42 | L17: 39 | N17: 29 | O17: 26 | Q17: 26 | R17: 32 | S17: 30 | U17: =+IFERROR(R17/T17,"") | V17: =+Hoja2!G7 -> 35.1 | X17: =+Hoja2!J7 -> 22.25 | AA17: =+IFERROR(X17/Z17,"") | AB17: =+Hoja2!K7 -> 20.025 | AD17: =Hoja2!N7 -> 15.3881 | AG17: =+IFERROR(AD17/AF17,"") | AH17: =+AD17*0.74 -> 11.387194 | AJ17: =Hoja2!R7 -> 13.84929 | AL17: =+_xlfn.XLOOKUP(A17,'[3]REQUERIMIENTO INBOUND'!B:B,'[3]REQUERIMIENTO INBOUND'!AI:AI,"",0) | AM17: =+IFERROR(AJ17/AL17,"") | AN17: =+AJ17*0.75 -> 10.386968 | AP17: =Hoja2!V7 -> 12.464361 | AR17: =+_xlfn.XLOOKUP(H17,'[3]REQUERIMIENTO INBOUND'!I:I,'[3]REQUERIMIENTO INBOUND'!AP:AP,"",0) -> 0 | AS17: =+IFERROR(AP17/AR17,"") | AT17: =+AP17*0.74 -> 9.2236271
A18: CANALES DIGITALES | B18: 2 | C18: 2 | D18: 0 | E18: 2 | F18: 2 | G18: =+'[4]Requerimiento Inbound'!$FF$12 -> 0 | H18: 12 | I18: 12 | J18: =+'[4]Requerimiento Inbound'!$FF$12 -> 0 | K18: 12 | L18: 12 | M18: =+'[4]Requerimiento Inbound'!$FF$12 -> 0 | N18: 12 | O18: 9 | P18: 0 | Q18: 9 | R18: 0 | S18: 0 | T18: 0 | U18: =+IFERROR(R18/T18,"") | V18: =+R18 -> 0 | X18: =+V18 -> 0 | Z18: 0 | AA18: =+IFERROR(X18/Z18,"") | AB18: =+X18 -> 0 | AD18: =+AB18 -> 0 | AF18: =+_xlfn.XLOOKUP(A18,'[3]REQUERIMIENTO INBOUND'!B:B,'[3]REQUERIMIENTO INBOUND'!AE:AE,"",0) -> 0 | AG18: =+IFERROR(AD18/AF18,"") | AH18: =+AD18 -> 0 | AJ18: =+AH18 -> 0 | AL18: =+_xlfn.XLOOKUP(A18,'[3]REQUERIMIENTO INBOUND'!B:B,'[3]REQUERIMIENTO INBOUND'!AI:AI,"",0) -> 0 | AM18: =+IFERROR(AJ18/AL18,"") | AN18: =+AJ18 -> 0 | AP18: =+AN18 -> 0 | AR18: =+_xlfn.XLOOKUP(H18,'[3]REQUERIMIENTO INBOUND'!I:I,'[3]REQUERIMIENTO INBOUND'!AP:AP,"",0) -> 0 | AS18: =+IFERROR(AP18/AR18,"") | AT18: =+AP18 -> 0
A19: TOTAL | B19: =+SUM(B14:B18) -> 433 | C19: =+SUM(C14:C18) -> 423 | D19: =+SUM(D14:D18) -> 429 | E19: =+SUM(E14:E18) -> 424 | F19: =+SUM(F14:F18) -> 405 | G19: =+SUM(G14:G18) -> 429 | H19: =+SUM(H14:H18) -> 416 | I19: =+SUM(I14:I18) -> 409 | ... T19: =+SUM(T14:T18) -> 451 | U19: =+R19/T19 -> 0.87804878 | V19: =+SUM(V14:V18) -> 380.59491 | X19: =+SUM(X14:X18) -> 400.83491 | Y19: =+SUM(Y14:Y15) -> 0 | Z19: =+SUM(Z14:Z18) -> 411 | AA19: =X19/Z19 -> 0.97526743 | AB19: =+SUM(AB14:AB17) -> 376.00006 | AD19: =+SUM(AD14:AD18) -> 395.60006 | AE19: =+SUM(AE14:AE18) -> 0 | AF19: =+SUM(AF14:AF18) -> 353 | AG19: =+AD19/AF19 -> 1.12068 | AH19: =+SUM(AH14:AH15) -> 327.45133 | AJ19: =ROUNDUP(+SUM(AJ14:AJ18),0) -> 395 | AL19: =+SUM(AL14:AL18) -> 327 | AM19: =AJ19/AL19 -> 1.2079511 | AN19: =+SUM(AN14:AN18) -> 391.0346 | AP19: =ROUNDUP(+SUM(AP14:AP18),0) -> 409 | AR19: =+SUM(AR14:AR18) -> 294 | AS19: =AP19/AR19 -> 1.3911565 | AT19: =+SUM(AT14:AT18) -> 405.43387
A20: RATIO CAPACITY | D20: =B19/D19 -> 1.009324 | G20: =E19/G19 -> 0.98834499 | J20: =H19/J19 -> 0.96969697 | M20: =K19/M19 -> 0.98834499 | P20: =+N19/P19 -> 0.95804196
A23: JACQUELINE | B23: =+B12 -> INI-ENE | C23: =+C12 -> REAL-ENE | D23: CAPACITY | E23: =+E12 -> INI-FEB | F23: =+F12 -> REAL-FEB | G23: CAPACITY | H23: =+H12 -> INI-MAR | I23: =+I12 -> REAL-MAR | J23: CAPACITY | K23: =+K12 -> INI-ABR | L23: =+L12 -> REAL-ABR | M23: CAPACITY | N23: INI-MAY | O23: REAL-MAY | P23: CAPACITY | Q23: CIERRE | R23: =+R12 -> INI-JUN | S23: REAL-JUN | T23: CAPACITY | U23: %COB | V23: =+V12 -> FORECAST CIERRE | W23: CIERRE | X23: =+X12 -> INI-JUL | Y23: =+Y12 -> REAL-JUL | Z23: CAPACITY | AA23: %COB | AB23: =+AB12 -> FORECAST CIERRE | AC23: CIERRE | AD23: =+AD12 -> INI-AGO | AE23: =+AE12 -> REAL-JUN | AF23: CAPACITY | AG23: %COB | AH23: =+AH12 -> FORECAST CIERRE | AI23: CIERRE | AJ23: =+AJ12 -> INI-SEP | AK23: =+AK12 -> REAL-JUN | AL23: CAPACITY | AM23: %COB | AN23: =+AN12 -> FORECAST CIERRE | AO23: CIERRE | AP23: =+AP12 -> INI-OCT | AQ23: =+AQ12 -> REAL-JUN | AR23: CAPACITY | AS23: %COB | AT23: =+AT12 -> FORECAST CIERRE
A24: UDAC BANCA MAYORISTA | B24: 35 | C24: 35 | D24: =+'[4]Requerimiento Inbound'!$FF$14 -> 38 | E24: 38 | F24: 38 | G24: =+'[4]Requerimiento Inbound'!$FF$14 -> 38 | H24: 38 | I24: 38 | J24: =+'[4]Requerimiento Inbound'!$FF$14 -> 38 | K24: 38 | L24: 38 | M24: =+'[4]Requerimiento Inbound'!$FF$14 -> 38 | N24: 38 | O24: 38 | P24: 38 | Q24: 38 | R24: 38 | S24: 38 | T24: 38 | U24: =+IFERROR(R24/T24,"") -> 1 | V24: =+R24-1 -> 37 | X24: =+V24 -> 37 | Z24: 38 | AA24: =+IFERROR(X24/Z24,"") -> 0.97368421 | AB24: =+R24-1 -> 37 | AC24: =+S24-1 -> 37 | AD24: =+AB24 -> 37 | AF24: =+_xlfn.XLOOKUP(A24,'[3]REQUERIMIENTO INBOUND'!B:B,'[3]REQUERIMIENTO INBOUND'!AE:AE,"",0) -> 38 | AG24: =+IFERROR(AD24/AF24,"") -> 0.97368421 | AH24: =+AD24-1 -> 36 | AJ24: =+AH24 -> 36 | AL24: =+_xlfn.XLOOKUP(A24,'[3]REQUERIMIENTO INBOUND'!B:B,'[3]REQUERIMIENTO INBOUND'!AI:AI,"",0) -> 38 | AM24: =+IFERROR(AJ24/AL24,"") -> 0.94736842 | AN24: =+AJ24-1 -> 35 | AP24: =+AN24 -> 35 | AR24: =+[2]Capacity!$AM$18 -> 39 | AS24: =+IFERROR(AP24/AR24,"") -> 0.8974359 | AT24: =+AP24-1 -> 34
A25: UDAC BANCA NEGOCIOS | B25: 22 | C25: 22 | D25: =+'[4]Requerimiento Inbound'!$FF$15 -> 20 | E25: 20 | F25: 20 | G25: =+'[4]Requerimiento Inbound'!$FF$15 -> 20 | H25: 20 | I25: 20 | J25: =+'[4]Requerimiento Inbound'!$FF$15 -> 20 | K25: 19 | L25: 19 | M25: =+'[4]Requerimiento Inbound'!$FF$15 -> 20 | N25: 20 | O25: 20 | P25: 20 | Q25: 20 | R25: 20 | S25: 20 | T25: 20 | U25: =+IFERROR(R25/T25,"") -> 1 | V25: =+R25 -> 20 | X25: =+V25 -> 20 | Z25: 20 | AA25: =+IFERROR(X25/Z25,"") -> 1 | AB25: =+R25-1 -> 19 | AD25: =+AB25 -> 19 | AF25: =+_xlfn.XLOOKUP(A25,'[3]REQUERIMIENTO INBOUND'!B:B,'[3]REQUERIMIENTO INBOUND'!AE:AE,"",0) -> 20 | AG25: =+IFERROR(AD25/AF25,"") -> 0.95 | AH25: =+AD25-1 -> 18 | AJ25: =+AH25 -> 18 | AL25: =+_xlfn.XLOOKUP(A25,'[3]REQUERIMIENTO INBOUND'!B:B,'[3]REQUERIMIENTO INBOUND'!AI:AI,"",0) -> 20 | AM25: =+IFERROR(AJ25/AL25,"") -> 0.9 | AN25: =+AJ25-1 -> 17 | AP25: =+AN25 -> 17 | AR25: =+[2]Capacity!$AM$19 -> 27 | AS25: =+IFERROR(AP25/AR25,"") -> 0.62962963 | AT25: =+AP25-1 -> 16
A26: UDAC PYME | B26: 35 | C26: 35 | D26: =+'[4]Requerimiento Inbound'!$FF$29 -> 53 | E26: 50 | F26: 48 | G26: =+'[4]Requerimiento Inbound'!$FF$29 -> 53 | H26: 40 | I26: 37 | J26: =+'[4]Requerimiento Inbound'!$FF$29 -> 53 | K26: 39 | L26: 39 | M26: =+'[4]Requerimiento Inbound'!$FF$29 -> 53 | N26: 37 | O26: 37 | P26: 53 | Q26: 37 | R26: =46-6 -> 40 | S26: 38 | T26: 33 | U26: =+IFERROR(R26/T26,"") -> 1.2121212 | V26: =+R26*(1-[1]TASA_ROTACION!L69) -> 38.285714 | X26: =+V26+6+12-18 -> 38.285714 | Z26: 34 | AA26: =+IFERROR(X26/Z26,"") -> 1.1260504 | AB26: =+X26*(1-[1]TASA_ROTACION!N69) -> 36.657717 | AD26: =+AB26 -> 36.657717 | AF26: =+_xlfn.XLOOKUP(A26,'[3]REQUERIMIENTO INBOUND'!B:B,'[3]REQUERIMIENTO INBOUND'!AE:AE,"",0) -> 32 | AG26: =+IFERROR(AD26/AF26,"") -> 1.1455537 | AH26: =+AD26*(1-[1]TASA_ROTACION!P69) -> 34.242717 | AJ26: =+AH26 -> 34.242717 | AL26: =+_xlfn.XLOOKUP(A26,'[3]REQUERIMIENTO INBOUND'!B:B,'[3]REQUERIMIENTO INBOUND'!AI:AI,"",0) -> 32 | AM26: =+IFERROR(AJ26/AL26,"") -> 1.0700849 | AN26: =+AJ26*(1-[1]TASA_ROTACION!R69) -> 32.175992 | AP26: =+AN26 -> 32.175992 | AR26: =+[2]Capacity!$AM$20 -> 33 | AS26: =+IFERROR(AP26/AR26,"") -> 0.97503006 | AT26: =+AP26*(1-[1]TASA_ROTACION!Y69) -> 32.175992
A27: UDAC PYME BUZON | B27: 17 | C27: 17 | D27: =+'[4]Requerimiento Inbound'!$FF$30 -> 0 | E27: 17 | F27: 17 | G27: =+'[4]Requerimiento Inbound'!$FF$30 -> 0 | H27: 18 | I27: 18 | J27: =+'[4]Requerimiento Inbound'!$FF$30 -> 0 | K27: 17 | L27: 17 | M27: =+'[4]Requerimiento Inbound'!$FF$30 -> 0 | N27: 16 | O27: 16 | P27: 0 | Q27: 16 | R27: 16 | S27: 16 | T27: 18 | U27: =+IFERROR(R27/T27,"") -> 0.88888889 | V27: =+R27 -> 16 | X27: =+V27 -> 16 | Z27: 18 | AA27: =+IFERROR(X27/Z27,"") -> 0.88888889 | AB27: =+X27 -> 16 | AD27: =+AB27 -> 16 | AF27: =+_xlfn.XLOOKUP(A27,'[3]REQUERIMIENTO INBOUND'!B:B,'[3]REQUERIMIENTO INBOUND'!AE:AE,"",0) -> 18 | AG27: =+IFERROR(AD27/AF27,"") -> 0.88888889 | AH27: =+AD27 -> 16 | AJ27: =+AH27 -> 16 | AL27: =+_xlfn.XLOOKUP(A27,'[3]REQUERIMIENTO INBOUND'!B:B,'[3]REQUERIMIENTO INBOUND'!AI:AI,"",0) -> 18 | AM27: =+IFERROR(AJ27/AL27,"") -> 0.88888889 | AN27: =+AJ27 -> 16 | AP27: =+AN27 -> 16 | AR27: =+[2]Capacity!$AM$21 -> 18 | AS27: =+IFERROR(AP27/AR27,"") -> 0.88888889 | AT27: =+AP27 -> 16
A28: OPERACIONES NO RECONOCIDAS | B28: 87 | C28: 86 | D28: =+'[4]Requerimiento Inbound'!$FF$13 -> 89 | E28: 94 | F28: 94 | G28: =+'[4]Requerimiento Inbound'!$FF$13 -> 89 | H28: 109 | I28: 109 | J28: =+'[4]Requerimiento Inbound'!$FF$13 -> 89 | K28: 106 | L28: 104 | M28: =+'[4]Requerimiento Inbound'!$FF$13 -> 89 | N28: 106 | O28: 106 | P28: 89 | Q28: 106 | R28: =111+6 -> 117 | S28: 118 | T28: 118 | U28: =+IFERROR(R28/T28,"") -> 0.99152542 | V28: =+R28*(1-[1]TASA_ROTACION!L54) -> 115.35487 | X28: =+V28-6+1 -> 110.35487 | Z28: 119 | AA28: =+IFERROR(X28/Z28,"") -> 0.92735186 | AB28: =+X28*(1-[1]TASA_ROTACION!N54) -> 109.67228 | AD28: =+AB28 -> 109.67228 | AF28: =+_xlfn.XLOOKUP(A28,'[3]REQUERIMIENTO INBOUND'!B:B,'[3]REQUERIMIENTO INBOUND'!AE:AE,"",0) -> 112 | AG28: =+IFERROR(AD28/AF28,"") -> 0.97921676 | AH28: =+AD28*(1-[1]TASA_ROTACION!P54) -> 108.1895 | AJ28: =+AH28 -> 108.1895 | AL28: =+_xlfn.XLOOKUP(A28,'[3]REQUERIMIENTO INBOUND'!B:B,'[3]REQUERIMIENTO INBOUND'!AI:AI,"",0) -> 116 | AM28: =+IFERROR(AJ28/AL28,"") -> 0.93266808 | AN28: =+AJ28*(1-[1]TASA_ROTACION!R54) -> 106.06707 | AP28: =+AN28 -> 106.06707 | AR28: =+[2]Capacity!$AM$22 -> 117 | AS28: =+IFERROR(AP28/AR28,"") -> 0.90655618 | AT28: =+AP28*(1-[1]TASA_ROTACION!Y54) -> 106.06707
A29: FUERA DE TURNO | B29: 34 | C29: 34 | D29: =+'[4]Requerimiento Inbound'!$FF$31 -> 34 | E29: 34 | F29: 34 | G29: =+'[4]Requerimiento Inbound'!$FF$31 -> 34 | H29: 34 | I29: 34 | J29: =+'[4]Requerimiento Inbound'!$FF$31 -> 34 | K29: 34 | L29: 34 | M29: =+'[4]Requerimiento Inbound'!$FF$31 -> 34 | N29: 34 | O29: 34 | P29: 34 | Q29: 34 | R29: 36 | S29: 36 | T29: 40 | U29: =+IFERROR(R29/T29,"") -> 0.9 | V29: =+R29 -> 36 | X29: =+V29 -> 36 | Z29: 39 | AA29: =+IFERROR(X29/Z29,"") -> 0.92307692 | AB29: =+R29 -> 36 | AD29: =+AB29 -> 36 | AF29: =+_xlfn.XLOOKUP(A29,'[3]REQUERIMIENTO INBOUND'!B:B,'[3]REQUERIMIENTO INBOUND'!AE:AE,"",0) -> 39 | AG29: =+IFERROR(AD29/AF29,"") -> 0.92307692 | AH29: =+AD29 -> 36 | AJ29: =+AH29 -> 36 | AL29: =+_xlfn.XLOOKUP(A29,'[3]REQUERIMIENTO INBOUND'!B:B,'[3]REQUERIMIENTO INBOUND'!AI:AI,"",0) -> 40 | AM29: =+IFERROR(AJ29/AL29,"") -> 0.9 | AN29: =+AJ29 -> 36 | AP29: =+AN29 -> 36 | AR29: =+[2]Capacity!$AM$23 -> 40 | AS29: =+IFERROR(AP29/AR29,"") -> 0.9 | AT29: =+AP29 -> 36
A30: OPERACIONES TRUNCAS | B30: 12 | C30: 12 | D30: =+'[4]Requerimiento Inbound'!$FF$9 -> 13 | E30: 13 | F30: 13 | G30: =+'[4]Requerimiento Inbound'!$FF$9 -> 13 | H30: 13 | I30: 13 | J30: =+'[4]Requerimiento Inbound'!$FF$9 -> 13 | K30: 13 | L30: 13 | M30: =+'[4]Requerimiento Inbound'!$FF$9 -> 13 | N30: 13 | O30: 13 | P30: 13 | Q30: 13 | R30: 13 | S30: 13 | T30: 13 | U30: =+IFERROR(R30/T30,"") -> 1 | V30: 13 | X30: =+V30 -> 13 | Z30: 13 | AA30: =+IFERROR(X30/Z30,"") -> 1 | AB30: =+R30 -> 13 | AD30: =+AB30 -> 13 | AF30: =+_xlfn.XLOOKUP(A30,'[3]REQUERIMIENTO INBOUND'!B:B,'[3]REQUERIMIENTO INBOUND'!AE:AE,"",0) -> 13 | AG30: =+IFERROR(AD30/AF30,"") -> 1 | AH30: 12 | AJ30: =+AH30 -> 12 | AL30: =+_xlfn.XLOOKUP(A30,'[3]REQUERIMIENTO INBOUND'!B:B,'[3]REQUERIMIENTO INBOUND'!AI:AI,"",0) -> 13 | AM30: =+IFERROR(AJ30/AL30,"") -> 0.92307692 | AN30: 12 | AP30: =+AN30 -> 12 | AR30: =+[2]Capacity!$AM$24 -> 13 | AS30: =+IFERROR(AP30/AR30,"") -> 0.92307692 | AT30: 12
A31: BANCA SEGURO | B31: 43 | C31: 43 | D31: =+'[4]Requerimiento Inbound'!$FF$27 -> 29 | E31: 41 | F31: 39 | G31: =+'[4]Requerimiento Inbound'!$FF$27 -> 29 | H31: 40 | I31: 40 | J31: =+'[4]Requerimiento Inbound'!$FF$27 -> 29 | K31: 39 | L31: 39 | M31: =+'[4]Requerimiento Inbound'!$FF$27 -> 29 | N31: 23 | O31: 23 | P31: 29 | Q31: 23 | R31: 23 | S31: 23 | T31: 25 | U31: =+IFERROR(R31/T31,"") -> 0.92 | V31: =+R31 -> 23 | X31: =+V31 -> 23 | Z31: 26 | AA31: =+IFERROR(X31/Z31,"") -> 0.88461538 | AB31: =+R31 -> 23 | AD31: =+AB31 -> 23 | AF31: =+_xlfn.XLOOKUP(A31,'[3]REQUERIMIENTO INBOUND'!B:B,'[3]REQUERIMIENTO INBOUND'!AE:AE,"",0) -> 26 | AG31: =+IFERROR(AD31/AF31,"") -> 0.88461538 | AH31: =+AD31 -> 23 | AJ31: =+AH31 -> 23 | AL31: =+_xlfn.XLOOKUP(A31,'[3]REQUERIMIENTO INBOUND'!B:B,'[3]REQUERIMIENTO INBOUND'!AI:AI,"",0) -> 24 | AM31: =+IFERROR(AJ31/AL31,"") -> 0.95833333 | AN31: =+AJ31 -> 23 | AP31: =+AN31 -> 23 | AR31: =+[2]Capacity!$AM$25 -> 26 | AS31: =+IFERROR(AP31/AR31,"") -> 0.88461538 | AT31: =+AP31 -> 23
A32: BANCA SEGURO RETENCIONES | B32: 23 | C32: 23 | D32: =+'[4]Requerimiento Inbound'!$FF$28 -> 23 | E32: 25 | F32: 25 | G32: =+'[4]Requerimiento Inbound'!$FF$28 -> 23 | H32: 26 | I32: 26 | J32: =+'[4]Requerimiento Inbound'!$FF$28 -> 23 | K32: 28 | L32: 28 | M32: =+'[4]Requerimiento Inbound'!$FF$28 -> 23 | N32: 26 | O32: 26 | P32: 23 | Q32: 26 | R32: 29 | S32: 29 | T32: 23 | U32: =+IFERROR(R32/T32,"") -> 1.2608696 | V32: =+R32 -> 29 | X32: =+V32 -> 29 | Z32: 23 | AA32: =+IFERROR(X32/Z32,"") -> 1.2608696 | AB32: =+R32 -> 29 | AD32: =+AB32 -> 29 | AF32: =+_xlfn.XLOOKUP(A32,'[3]REQUERIMIENTO INBOUND'!B:B,'[3]REQUERIMIENTO INBOUND'!AE:AE,"",0) -> 23 | AG32: =+IFERROR(AD32/AF32,"") -> 1.2608696 | AH32: =+AD32 -> 29 | AJ32: =+AH32 -> 29 | AL32: =+_xlfn.XLOOKUP(A32,'[3]REQUERIMIENTO INBOUND'!B:B,'[3]REQUERIMIENTO INBOUND'!AI:AI,"",0) -> 23 | AM32: =+IFERROR(AJ32/AL32,"") -> 1.2608696 | AN32: =+AJ32 -> 29 | AP32: =+AN32 -> 29 | AR32: =+[2]Capacity!$AM$26 -> 23 | AS32: =+IFERROR(AP32/AR32,"") -> 1.2608696 | AT32: =+AP32 -> 29
A33: RETENCIONES | B33: 14 | C33: 14 | D33: =+'[4]Requerimiento Inbound'!$FF$22 -> 15 | E33: 15 | F33: 15 | G33: =+'[4]Requerimiento Inbound'!$FF$22 -> 15 | H33: 15 | I33: 15 | J33: =+'[4]Requerimiento Inbound'!$FF$22 -> 15 | K33: 15 | L33: 15 | M33: =+'[4]Requerimiento Inbound'!$FF$22 -> 15 | N33: 15 | O33: 15 | P33: 15 | Q33: 15 | R33: 15 | S33: 15 | T33: 15 | U33: =+IFERROR(R33/T33,"") -> 1 | V33: =+R33 -> 15 | X33: =+V33 -> 15 | Z33: 15 | AA33: =+IFERROR(X33/Z33,"") -> 1 | AB33: =+R33 -> 15 | AD33: =+AB33 -> 15 | AF33: =+_xlfn.XLOOKUP(A33,'[3]REQUERIMIENTO INBOUND'!B:B,'[3]REQUERIMIENTO INBOUND'!AE:AE,"",0) -> 15 | AG33: =+IFERROR(AD33/AF33,"") -> 1 | AH33: =+AD33 -> 15 | AJ33: =+AH33 -> 15 | AL33: =+_xlfn.XLOOKUP(A33,'[3]REQUERIMIENTO INBOUND'!B:B,'[3]REQUERIMIENTO INBOUND'!AI:AI,"",0) -> 15 | AM33: =+IFERROR(AJ33/AL33,"") -> 1 | AN33: =+AJ33 -> 15 | AP33: =+AN33 -> 15 | AR33: =+[2]Capacity!$AM$27 -> 15 | AS33: =+IFERROR(AP33/AR33,"") -> 1 | AT33: =+AP33 -> 15
A34: HELPDESK SPE | B34: 33 | C34: 33 | D34: =+'[4]Requerimiento Inbound'!$FF$17 -> 34 | E34: 34 | F34: 33 | G34: =+'[4]Requerimiento Inbound'!$FF$17 -> 34 | H34: 34 | I34: 34 | J34: =+'[4]Requerimiento Inbound'!$FF$17 -> 34 | K34: 34 | L34: 34 | M34: =+'[4]Requerimiento Inbound'!$FF$17 -> 34 | N34: 34 | O34: 34 | P34: 34 | Q34: 34 | R34: 34 | S34: 34 | T34: 34 | U34: =+IFERROR(R34/T34,"") -> 1 | V34: =+R34 -> 34 | X34: =+V34 -> 34 | Z34: 34 | AA34: =+IFERROR(X34/Z34,"") -> 1 | AB34: =+R34 -> 34 | AD34: =+AB34 -> 34 | AF34: =+_xlfn.XLOOKUP(A34,'[3]REQUERIMIENTO INBOUND'!B:B,'[3]REQUERIMIENTO INBOUND'!AE:AE,"",0) -> 34 | AG34: =+IFERROR(AD34/AF34,"") -> 1 | AH34: =+AD34 -> 34 | AJ34: =+AH34 -> 34 | AL34: =+_xlfn.XLOOKUP(A34,'[3]REQUERIMIENTO INBOUND'!B:B,'[3]REQUERIMIENTO INBOUND'!AI:AI,"",0) -> 34 | AM34: =+IFERROR(AJ34/AL34,"") -> 1 | AN34: =+AJ34 -> 34 | AP34: =+AN34 -> 34 | AR34: =+[2]Capacity!$AM$28 -> 26 | AS34: =+IFERROR(AP34/AR34,"") -> 1.3076923 | AT34: =+AP34 -> 34
A35: INVERSIONES | B35: 3 | C35: 3 | D35: =+'[4]Requerimiento Inbound'!$FF$21 -> 3 | E35: 5 | F35: 5 | G35: =+'[4]Requerimiento Inbound'!$FF$21 -> 3 | H35: 5 | I35: 5 | J35: =+'[4]Requerimiento Inbound'!$FF$21 -> 3 | K35: 5 | L35: 5 | M35: =+'[4]Requerimiento Inbound'!$FF$21 -> 3 | N35: 5 | O35: 5 | P35: 3 | Q35: 5 | R35: 5 | S35: 5 | T35: 5 | U35: =+IFERROR(R35/T35,"") -> 1 | V35: =+R35 -> 5 | X35: =+V35 -> 5 | Z35: 5 | AA35: =+IFERROR(X35/Z35,"") -> 1 | AB35: =+R35 -> 5 | AD35: =+AB35 -> 5 | AF35: =+_xlfn.XLOOKUP(A35,'[3]REQUERIMIENTO INBOUND'!B:B,'[3]REQUERIMIENTO INBOUND'!AE:AE,"",0) -> 5 | AG35: =+IFERROR(AD35/AF35,"") -> 1 | AH35: =+AD35 -> 5 | AJ35: =+AH35 -> 5 | AL35: =+_xlfn.XLOOKUP(A35,'[3]REQUERIMIENTO INBOUND'!B:B,'[3]REQUERIMIENTO INBOUND'!AI:AI,"",0) -> 5 | AM35: =+IFERROR(AJ35/AL35,"") -> 1 | AN35: =+AJ35 -> 5 | AP35: =+AN35 -> 5 | AR35: =+[2]Capacity!$AM$29 -> 5 | AS35: =+IFERROR(AP35/AR35,"") -> 1 | AT35: =+AP35 -> 5
A36: ENALTA | B36: 20 | C36: 20 | D36: =+'[4]Requerimiento Inbound'!$FF$7 -> 22 | E36: 22 | F36: 22 | G36: =+'[4]Requerimiento Inbound'!$FF$7 -> 22 | H36: 22 | I36: 22 | J36: =+'[4]Requerimiento Inbound'!$FF$7 -> 22 | K36: 23 | L36: 22 | M36: =+'[4]Requerimiento Inbound'!$FF$7 -> 22 | N36: 22 | O36: 22 | P36: 22 | Q36: 22 | R36: 22 | S36: 22 | T36: 22 | U36: =+IFERROR(R36/T36,"") -> 1 | V36: =+R36 -> 22 | X36: =+V36 -> 22 | Z36: 22 | AA36: =+IFERROR(X36/Z36,"") -> 1 | AB36: =+R36 -> 22 | AD36: =+AB36 -> 22 | AF36: =+_xlfn.XLOOKUP(A36,'[3]REQUERIMIENTO INBOUND'!B:B,'[3]REQUERIMIENTO INBOUND'!AE:AE,"",0) -> 22 | AG36: =+IFERROR(AD36/AF36,"") -> 1 | AH36: =+AD36 -> 22 | AJ36: =+AH36 -> 22 | AL36: =+_xlfn.XLOOKUP(A36,'[3]REQUERIMIENTO INBOUND'!B:B,'[3]REQUERIMIENTO INBOUND'!AI:AI,"",0) -> 22 | AM36: =+IFERROR(AJ36/AL36,"") -> 1 | AN36: =+AJ36 -> 22 | AP36: =+AN36 -> 22 | AR36: =+[2]Capacity!$AM$30 -> 22 | AS36: =+IFERROR(AP36/AR36,"") -> 1 | AT36: =+AP36 -> 22
A37: LINEA TU BIENESTAR | B37: 14 | C37: 14 | D37: =+'[4]Requerimiento Inbound'!$FF$18 -> 14 | E37: 14 | F37: 14 | G37: =+'[4]Requerimiento Inbound'!$FF$18 -> 14 | H37: 14 | I37: 14 | J37: =+'[4]Requerimiento Inbound'!$FF$18 -> 14 | K37: 13 | L37: 13 | M37: =+'[4]Requerimiento Inbound'!$FF$18 -> 14 | N37: 14 | O37: 14 | P37: 14 | Q37: 14 | R37: 14 | S37: 14 | T37: 14 | U37: =+IFERROR(R37/T37,"") -> 1 | V37: =+R37 -> 14 | X37: =+V37 -> 14 | Z37: 14 | AA37: =+IFERROR(X37/Z37,"") -> 1 | AB37: =+R37 -> 14 | AD37: =+AB37 -> 14 | AF37: =+_xlfn.XLOOKUP(A37,'[3]REQUERIMIENTO INBOUND'!B:B,'[3]REQUERIMIENTO INBOUND'!AE:AE,"",0) -> 14 | AG37: =+IFERROR(AD37/AF37,"") -> 1 | AH37: =+AD37 -> 14 | AJ37: =+AH37 -> 14 | AL37: =+_xlfn.XLOOKUP(A37,'[3]REQUERIMIENTO INBOUND'!B:B,'[3]REQUERIMIENTO INBOUND'!AI:AI,"",0) -> 14 | AM37: =+IFERROR(AJ37/AL37,"") -> 1 | AN37: =+AJ37 -> 14 | AP37: =+AN37 -> 14 | AR37: =+[2]Capacity!$AM$31 -> 14 | AS37: =+IFERROR(AP37/AR37,"") -> 1 | AT37: =+AP37 -> 14
A38: AGENTE | B38: 11 | C38: 10 | D38: =+'[4]Requerimiento Inbound'!$FF$19 -> 10 | E38: 10 | F38: 10 | G38: =+'[4]Requerimiento Inbound'!$FF$19 -> 10 | H38: 10 | I38: 10 | J38: =+'[4]Requerimiento Inbound'!$FF$19 -> 10 | K38: 10 | L38: 10 | M38: =+'[4]Requerimiento Inbound'!$FF$19 -> 10 | N38: 10 | O38: 10 | P38: 10 | Q38: 10 | R38: 10 | S38: 9 | T38: 10 | U38: =+IFERROR(R38/T38,"") -> 1 | V38: =+R38 -> 10 | X38: =+V38 -> 10 | Z38: 10 | AA38: =+IFERROR(X38/Z38,"") -> 1 | AB38: =+R38 -> 10 | AD38: =+AB38 -> 10 | AF38: =+_xlfn.XLOOKUP(A38,'[3]REQUERIMIENTO INBOUND'!B:B,'[3]REQUERIMIENTO INBOUND'!AE:AE,"",0) -> 10 | AG38: =+IFERROR(AD38/AF38,"") -> 1 | AH38: =+AD38 -> 10 | AJ38: =+AH38 -> 10 | AL38: =+_xlfn.XLOOKUP(A38,'[3]REQUERIMIENTO INBOUND'!B:B,'[3]REQUERIMIENTO INBOUND'!AI:AI,"",0) -> 10 | AM38: =+IFERROR(AJ38/AL38,"") -> 1 | AN38: =+AJ38 -> 10 | AP38: =+AN38 -> 10 | AR38: =+[2]Capacity!$AM$32 -> 10 | AS38: =+IFERROR(AP38/AR38,"") -> 1 | AT38: =+AP38 -> 10
A39: CENTRAL TELEFONICA | B39: 3 | C39: 3 | D39: =+'[4]Requerimiento Inbound'!$FF$10 -> 5 | E39: 3 | F39: 3 | G39: =+'[4]Requerimiento Inbound'!$FF$10 -> 5 | H39: 3 | I39: 3 | J39: =+'[4]Requerimiento Inbound'!$FF$10 -> 5 | K39: 4 | L39: 4 | M39: =+'[4]Requerimiento Inbound'!$FF$10 -> 5 | N39: 5 | O39: 5 | P39: 5 | Q39: 5 | R39: 5 | S39: 5 | T39: 5 | U39: =+IFERROR(R39/T39,"") -> 1 | V39: =+R39 -> 5 | X39: =+V39 -> 5 | Z39: 5 | AA39: =+IFERROR(X39/Z39,"") -> 1 | AB39: =+R39 -> 5 | AD39: =+AB39 -> 5 | AF39: =+_xlfn.XLOOKUP(A39,'[3]REQUERIMIENTO INBOUND'!B:B,'[3]REQUERIMIENTO INBOUND'!AE:AE,"",0) -> 5 | AG39: =+IFERROR(AD39/AF39,"") -> 1 | AH39: =+AD39 -> 5 | AJ39: =+AH39 -> 5 | AL39: =+_xlfn.XLOOKUP(A39,'[3]REQUERIMIENTO INBOUND'!B:B,'[3]REQUERIMIENTO INBOUND'!AI:AI,"",0) -> 5 | AM39: =+IFERROR(AJ39/AL39,"") -> 1 | AN39: =+AJ39 -> 5 | AP39: =+AN39 -> 5 | AR39: =+[2]Capacity!$AM$33 -> 5 | AS39: =+IFERROR(AP39/AR39,"") -> 1 | AT39: =+AP39 -> 5
A40: FACTURACION ELECTRONICA | B40: 4 | C40: 4 | D40: =+'[4]Requerimiento Inbound'!$FF$32 -> 5 | E40: 4 | F40: 4 | G40: =+'[4]Requerimiento Inbound'!$FF$32 -> 5 | H40: 4 | I40: 4 | J40: =+'[4]Requerimiento Inbound'!$FF$32 -> 5 | K40: 4 | L40: 4 | M40: =+'[4]Requerimiento Inbound'!$FF$32 -> 5 | N40: 4 | O40: 4 | P40: 5 | Q40: 4 | R40: 4 | S40: 4 | T40: 5 | U40: =+IFERROR(R40/T40,"") -> 0.8 | V40: =+R40 -> 4 | X40: =+V40 -> 4 | Z40: 5 | AA40: =+IFERROR(X40/Z40,"") -> 0.8 | AB40: =+X40 -> 4 | AD40: =+AB40 -> 4 | AF40: =+_xlfn.XLOOKUP(A40,'[3]REQUERIMIENTO INBOUND'!B:B,'[3]REQUERIMIENTO INBOUND'!AE:AE,"",0) -> 5 | AG40: =+IFERROR(AD40/AF40,"") -> 0.8 | AH40: =+AD40 -> 4 | AJ40: =+AH40 -> 4 | AL40: =+_xlfn.XLOOKUP(A40,'[3]REQUERIMIENTO INBOUND'!B:B,'[3]REQUERIMIENTO INBOUND'!AI:AI,"",0) -> 5 | AM40: =+IFERROR(AJ40/AL40,"") -> 0.8 | AN40: =+AJ40 -> 4 | AP40: =+AN40 -> 4 | AR40: =+[2]Capacity!$AM$34 -> 5 | AS40: =+IFERROR(AP40/AR40,"") -> 0.8 | AT40: =+AP40 -> 4
A41: BLOQUEOS | B41: 15 | C41: 15 | D41: =+'[4]Requerimiento Inbound'!$FF$25 -> 0 | E41: 15 | F41: 15 | G41: =+'[4]Requerimiento Inbound'!$FF$25 -> 0 | H41: 14 | I41: 14 | J41: =+'[4]Requerimiento Inbound'!$FF$25 -> 0 | K41: 14 | L41: 14 | M41: =+'[4]Requerimiento Inbound'!$FF$25 -> 0 | N41: 14 | O41: 14 | P41: 0 | Q41: 14 | T41: 0 | U41: =+IFERROR(R41/T41,"") | X41: =+V41 -> 0 | Z41: 0 | AA41: =+IFERROR(X41/Z41,"") | AD41: =+AB41 -> 0 | AF41: =+_xlfn.XLOOKUP(A41,'[3]REQUERIMIENTO INBOUND'!B:B,'[3]REQUERIMIENTO INBOUND'!AE:AE,"",0) -> 0 | AG41: =+IFERROR(AD41/AF41,"") | AH41: 13 | AJ41: =+AH41 -> 13 | AL41: =+_xlfn.XLOOKUP(A41,'[3]REQUERIMIENTO INBOUND'!B:B,'[3]REQUERIMIENTO INBOUND'!AI:AI,"",0) -> 0 | AM41: =+IFERROR(AJ41/AL41,"") | AN41: 13 | AP41: =+AN41 -> 13 | AR41: =+[2]Capacity!$AM$35 -> 0 | AS41: =+IFERROR(AP41/AR41,"") | AT41: 13
A42: TOTAL | B42: =+SUM(B24:B41) -> 425 | C42: =+SUM(C24:C41) -> 423 | D42: =+SUM(D24:D41) -> 407 | E42: =+SUM(E24:E41) -> 454 | F42: =+SUM(F24:F41) -> 449 | G42: =+SUM(G24:G41) -> 407 | H42: =+SUM(H24:H41) -> 459 | I42: =+SUM(I24:I41) -> 456 | J42: =+SUM(J24:J40) -> 407 | K42: =+SUM(K24:K41) -> 455 | L42: =+SUM(L24:L41) -> 452 | M42: =+SUM(M24:M41) -> 407 | N42: =+SUM(N24:N41) -> 436 | O42: =+SUM(O24:O41) -> 436 | P42: =+SUM(P24:P41) -> 407 | Q42: =+SUM(Q24:Q41) -> 436 | R42: =+SUM(R24:R41) -> 441 | ... T42: =+SUM(T24:T41) -> 438 | U42: =+R42/T42 -> 1.0068493 | V42: =+SUM(V24:V41) -> 436.64059 | X42: =+SUM(X24:X41) -> 431.64059 | Z42: =+SUM(Z24:Z41) -> 440 | AA42: =+X42/Z42 -> 0.98100133 | AB42: =+SUM(AB24:AB41) -> 428.32999 | AD42: =+SUM(AD24:AD41) -> 428.32999 | AF42: =+SUM(AF24:AF41) -> 431 | AG42: =+AD42/AF42 -> 0.99380509 | AH42: =+SUM(AH24:AH41) -> 434.43221 | AJ42: =ROUNDDOWN(+SUM(AJ24:AJ41),0) -> 434 | AL42: =+SUM(AL24:AL41) -> 434 | AM42: =+AJ42/AL42 -> 1 | AN42: =+SUM(AN24:AN41) -> 428.24306 | AP42: =ROUNDDOWN(+SUM(AP24:AP41),0) -> 428 | AR42: =+SUM(AR24:AR41) -> 438 | AS42: =+AP42/AR42 -> 0.97716895 | AT42: =+SUM(AT24:AT41) -> 426.24306
A43: RATIO CAPACITY | P43: =+N42/P42 -> 1.0712531 | T43: =+R42/T42 -> 1.0068493
...

Sheet Hoja2
A1: MAYO | E1: JUNIO | I1: JULIO | M1: AGOSTO | Q1: SEPTIEMBRE | U1: OCTUBRE
A3: TRAINEE M1 | B3: 25 | C3: =+B3*(1-$B$12) -> 24.5 | E3: TRAINEE M1 | F3: =+Hoja4!R7 -> 30 | G3: =+F3*(1-$B$12) -> 29.4 | I3: TRAINEE M1 | J3: =+Hoja4!X7 -> 20 | K3: =+J3*(1-$B$12) -> 19.6 | M3: TRAINEE M1 | N3: =+Hoja4!AD7 -> 20 | O3: =+N3*(1-$B$12) -> 19.6 | Q3: TRAINEE M1 | R3: =+Hoja4!AJ7 -> 20 | S3: =+R3*(1-$B$12) -> 19.6 | U3: TRAINEE M1 | V3: =+Hoja4!AP7 -> 20 | W3: =+V3*(1-$B$12) -> 19.6
A4: TRAINEE M2 | B4: 21 | C4: =+B4*(1-$C$12) -> 19.32 | E4: TRAINEE M2 | F4: =+Hoja4!R6 -> 22 | G4: =+F4*(1-$C$12) -> 20.24 | I4: TRAINEE M2 | J4: =+G3 -> 29.4 | K4: =+J4*(1-$C$12) -> 27.048 | M4: TRAINEE M2 | N4: =+K3 -> 19.6 | O4: =+N4*(1-$C$12) -> 18.032 | Q4: TRAINEE M2 | R4: =+O4 -> 18.032 | S4: =+R4*(1-$C$12) -> 16.58944 | U4: TRAINEE M2 | V4: =+S4 -> 16.58944 | W4: =+V4*(1-$C$12) -> 15.262285
A5: TRAINEE M3 | B5: 27 | C5: =+B5*(1-$D$12) -> 24.57 | E5: TRAINEE M3 | F5: 19 | G5: =+F5*(1-$D$12) -> 17.29 | I5: TRAINEE M3 | J5: =+G4 -> 20.24 | K5: =+J5*(1-$D$12) -> 18.4184 | M5: TRAINEE M3 | N5: =+K4 -> 27.048 | O5: =+N5*(1-$D$12) -> 24.61368 | Q5: TRAINEE M3 | R5: =+O5 -> 24.61368 | S5: =+R5*(1-$D$12) -> 22.398449 | U5: TRAINEE M3 | V5: =+S5 -> 22.398449 | W5: =+V5*(1-$D$12) -> 20.382588
A6: TRAINEE M4 | B6: 32 | C6: =+B6*(1-$E$12) -> 28.48 | E6: TRAINEE M4 | F6: 25 | G6: =+F6*(1-$E$12) -> 22.25 | I6: TRAINEE M4 | J6: =+G5 -> 17.29 | K6: =+J6*(1-$E$12) -> 15.3881 | M6: TRAINEE M4 | N6: =+K5 -> 18.4184 | O6: =+N6*(1-$E$12) -> 16.392376 | Q6: TRAINEE M4 | R6: =+O6 -> 16.392376 | S6: =+R6*(1-$E$12) -> 14.589215 | U6: TRAINEE M4 | V6: =+S6 -> 14.589215 | W6: =+V6*(1-$E$12) -> 12.984401
A7: TRAINEE M5 | B7: 29 | C7: =+B7*0.9 -> 26.1 | E7: TRAINEE M5 | F7: 39 | G7: =+F7*0.9 -> 35.1 | I7: TRAINEE M5 | J7: =+G6 -> 22.25 | K7: =+J7*0.9 -> 20.025 | M7: TRAINEE M5 | N7: =+K6 -> 15.3881 | O7: =+N7*0.9 -> 13.84929 | Q7: TRAINEE M5 | R7: =+O7 -> 13.84929 | S7: =+R7*0.9 -> 12.464361 | U7: TRAINEE M5 | V7: =+S7 -> 12.464361 | W7: =+V7*0.9 -> 11.217925
B11: m1 | C11: m2 | D11: m3 | E11: m4 | F11: m5 | G11: m6
A12: TRAINEE | B12: 0.02 | C12: 0.08 | D12: 0.09 | E12: 0.11 | F12: 0.22 | G12: 0.3
