Workbook

Sheet Datos Históricos
A1: 📊 REGISTRO HISTÓRICO DE INGRESOS Y EGRESOS DE PERSONAS
A2: Ingresa datos reales en las celdas azules (Ingresos) y rojas (Egresos). Las columnas Neto se calculan automáticamente.
A3: AÑO | B3: ENE | E3: FEB | H3: MAR | K3: ABR | N3: MAY | Q3: JUN | T3: JUL | W3: AGO | Z3: SEP | AC3: OCT | AF3: NOV | AI3: DIC | AL3: TOT INGRESOS | AM3: TOT EGRESOS | AN3: NETO ACUM
B4: Ingresos | C4: Egresos | D4: Neto | E4: Ingresos | F4: Egresos | G4: Neto | H4: Ingresos | I4: Egresos | J4: Neto | K4: Ingresos | L4: Egresos | M4: Neto | N4: Ingresos | O4: Egresos | P4: Neto | Q4: Ingresos | R4: Egresos | S4: Neto | T4: Ingresos | U4: Egresos | V4: Neto | W4: Ingresos | X4: Egresos | Y4: Neto | Z4: Ingresos | AA4: Egresos | AB4: Neto | AC4: Ingresos | AD4: Egresos | AE4: Neto | AF4: Ingresos | AG4: Egresos | AH4: Neto | AI4: Ingresos | AJ4: Egresos | AK4: Neto | AL4: Ingresos | AM4: Egresos | AN4: Neto
A5: 2024 | B5: 442 | C5: 20 | D5: =IF(AND(B5<>"",C5<>""),B5-C5,"") -> 422 | E5: 438 | F5: 18 | G5: =IF(AND(E5<>"",F5<>""),E5-F5,"") -> 420 | H5: 426 | I5: 29 | J5: =IF(AND(H5<>"",I5<>""),H5-I5,"") -> 397 | K5: 429 | L5: 15 | M5: =IF(AND(K5<>"",L5<>""),K5-L5,"") -> 414 | N5: 467 | O5: 25 | P5: =IF(AND(N5<>"",O5<>""),N5-O5,"") -> 442 | Q5: 476 | R5: 20 | S5: =IF(AND(Q5<>"",R5<>""),Q5-R5,"") -> 456 | T5: 491 | U5: 35 | V5: =IF(AND(T5<>"",U5<>""),T5-U5,"") -> 456 | W5: 473 | X5: 30 | Y5: =IF(AND(W5<>"",X5<>""),W5-X5,"") -> 443 | Z5: 450 | AA5: 45 | AB5: =IF(AND(Z5<>"",AA5<>""),Z5-AA5,"") -> 405 | AC5: 416 | AD5: 29 | AE5: =IF(AND(AC5<>"",AD5<>""),AC5-AD5,"") -> 387 | AF5: 387 | AG5: 24 | AH5: =IF(AND(AF5<>"",AG5<>""),AF5-AG5,"") -> 363 | AI5: 379 | AJ5: 19 | AK5: =IF(AND(AI5<>"",AJ5<>""),AI5-AJ5,"") -> 360 | AL5: =IFERROR(SUMPRODUCT((B5+E5+H5+K5+N5+Q5+T5+W5+Z5+AC5+AF5+AI5)*1),0) -> 5274 | AM5: =IFERROR(SUMPRODUCT((C5+F5+I5+L5+O5+R5+U5+X5+AA5+AD5+AG5+AJ5)*1),0) -> 309 | AN5: =AL5-AM5 -> 4965
A6: 2025 | B6: 425 | C6: 18 | D6: =IF(AND(B6<>"",C6<>""),B6-C6,"") -> 407 | E6: 448 | F6: 10 | G6: =IF(AND(E6<>"",F6<>""),E6-F6,"") -> 438 | H6: 397 | I6: 24 | J6: =IF(AND(H6<>"",I6<>""),H6-I6,"") -> 373 | K6: 363 | L6: 19 | M6: =IF(AND(K6<>"",L6<>""),K6-L6,"") -> 344 | N6: 343 | O6: 25 | P6: =IF(AND(N6<>"",O6<>""),N6-O6,"") -> 318 | Q6: 333 | R6: 21 | S6: =IF(AND(Q6<>"",R6<>""),Q6-R6,"") -> 312 | T6: 334 | U6: 24 | V6: =IF(AND(T6<>"",U6<>""),T6-U6,"") -> 310 | W6: 337 | X6: 18 | Y6: =IF(AND(W6<>"",X6<>""),W6-X6,"") -> 319 | Z6: 353 | AA6: 29 | AB6: =IF(AND(Z6<>"",AA6<>""),Z6-AA6,"") -> 324 | AC6: 351 | AD6: 20 | AE6: =IF(AND(AC6<>"",AD6<>""),AC6-AD6,"") -> 331 | AF6: 321 | AG6: 23 | AH6: =IF(AND(AF6<>"",AG6<>""),AF6-AG6,"") -> 298 | AI6: 309 | AJ6: 24 | AK6: =IF(AND(AI6<>"",AJ6<>""),AI6-AJ6,"") -> 285 | AL6: =IFERROR(SUMPRODUCT((B6+E6+H6+K6+N6+Q6+T6+W6+Z6+AC6+AF6+AI6)*1),0) -> 4314 | AM6: =IFERROR(SUMPRODUCT((C6+F6+I6+L6+O6+R6+U6+X6+AA6+AD6+AG6+AJ6)*1),0) -> 255 | AN6: =AL6-AM6 -> 4059
A7: 2026 | B7: 276 | C7: 18 | D7: =IF(AND(B7<>"",C7<>""),B7-C7,"") -> 258 | E7: 275 | F7: 24 | G7: =IF(AND(E7<>"",F7<>""),E7-F7,"") -> 251 | H7: 272 | I7: 16 | J7: =IF(AND(H7<>"",I7<>""),H7-I7,"") -> 256 | K7: 280 | L7: 13 | M7: =IF(AND(K7<>"",L7<>""),K7-L7,"") -> 267 | N7: 290 | O7: 6 | P7: =IF(AND(N7<>"",O7<>""),N7-O7,"") -> 284 | S7: =IF(AND(Q7<>"",R7<>""),Q7-R7,"") | V7: =IF(AND(T7<>"",U7<>""),T7-U7,"") | Y7: =IF(AND(W7<>"",X7<>""),W7-X7,"") | AB7: =IF(AND(Z7<>"",AA7<>""),Z7-AA7,"") | AE7: =IF(AND(AC7<>"",AD7<>""),AC7-AD7,"") | AH7: =IF(AND(AF7<>"",AG7<>""),AF7-AG7,"") | AK7: =IF(AND(AI7<>"",AJ7<>""),AI7-AJ7,"") | AL7: =IFERROR(SUMPRODUCT((B7+E7+H7+K7+N7+Q7+T7+W7+Z7+AC7+AF7+AI7)*1),0) -> 1393 | AM7: =IFERROR(SUMPRODUCT((C7+F7+I7+L7+O7+R7+U7+X7+AA7+AD7+AG7+AJ7)*1),0) -> 77 | AN7: =AL7-AM7 -> 1316
A8: ⬇ Agrega un nuevo año aquí: escribe el año en col A, luego llena Ingresos y Egresos por mes

Sheet Análisis & Predicción
A1: 🔮 ANÁLISIS ESTADÍSTICO Y PREDICCIÓN — FORECAST.LINEAR + ESCENARIOS
A2: Predicción por REGRESIÓN LINEAL (FORECAST.LINEAR) mes a mes. Agrega más años históricos en Hoja 1 y esta hoja se actualiza automáticamente.
A4: DATOS POR AÑO (tabla auxiliar para regresión — no modificar)
A5: Periodo | B5: Año | C5: ENE Ing | D5: FEB Ing | E5: MAR Ing | F5: ABR Ing | G5: MAY Ing | H5: JUN Ing | I5: JUL Ing | J5: AGO Ing | K5: SEP Ing | L5: OCT Ing | M5: NOV Ing | N5: DIC Ing | O5: ENE Egr | P5: FEB Egr | Q5: MAR Egr | R5: ABR Egr | S5: MAY Egr | T5: JUN Egr | U5: JUL Egr | V5: AGO Egr | W5: SEP Egr | X5: OCT Egr | Y5: NOV Egr | Z5: DIC Egr
A6: 1 | B6: 2024 | C6: ='Datos Históricos'!B5 -> 442 | D6: ='Datos Históricos'!E5 -> 438 | E6: ='Datos Históricos'!H5 -> 426 | F6: ='Datos Históricos'!K5 -> 429 | G6: ='Datos Históricos'!N5 -> 467 | H6: ='Datos Históricos'!Q5 -> 476 | I6: ='Datos Históricos'!T5 -> 491 | J6: ='Datos Históricos'!W5 -> 473 | K6: ='Datos Históricos'!Z5 -> 450 | L6: ='Datos Históricos'!AC5 -> 416 | M6: ='Datos Históricos'!AF5 -> 387 | N6: ='Datos Históricos'!AI5 -> 379 | O6: ='Datos Históricos'!C5 -> 20 | P6: ='Datos Históricos'!F5 -> 18 | Q6: ='Datos Históricos'!I5 -> 29 | R6: ='Datos Históricos'!L5 -> 15 | S6: ='Datos Históricos'!O5 -> 25 | T6: ='Datos Históricos'!R5 -> 20 | U6: ='Datos Históricos'!U5 -> 35 | V6: ='Datos Históricos'!X5 -> 30 | W6: ='Datos Históricos'!AA5 -> 45 | X6: ='Datos Históricos'!AD5 -> 29 | Y6: ='Datos Históricos'!AG5 -> 24 | Z6: ='Datos Históricos'!AJ5 -> 19
A7: 2 | B7: 2025 | C7: ='Datos Históricos'!B6 -> 425 | D7: ='Datos Históricos'!E6 -> 448 | E7: ='Datos Históricos'!H6 -> 397 | F7: ='Datos Históricos'!K6 -> 363 | G7: ='Datos Históricos'!N6 -> 343 | H7: ='Datos Históricos'!Q6 -> 333 | I7: ='Datos Históricos'!T6 -> 334 | J7: ='Datos Históricos'!W6 -> 337 | K7: ='Datos Históricos'!Z6 -> 353 | L7: ='Datos Históricos'!AC6 -> 351 | M7: ='Datos Históricos'!AF6 -> 321 | N7: ='Datos Históricos'!AI6 -> 309 | O7: ='Datos Históricos'!C6 -> 18 | P7: ='Datos Históricos'!F6 -> 10 | Q7: ='Datos Históricos'!I6 -> 24 | R7: ='Datos Históricos'!L6 -> 19 | S7: ='Datos Históricos'!O6 -> 25 | T7: ='Datos Históricos'!R6 -> 21 | U7: ='Datos Históricos'!U6 -> 24 | V7: ='Datos Históricos'!X6 -> 18 | W7: ='Datos Históricos'!AA6 -> 29 | X7: ='Datos Históricos'!AD6 -> 20 | Y7: ='Datos Históricos'!AG6 -> 23 | Z7: ='Datos Históricos'!AJ6 -> 24
A8: 3 | B8: 2026 | C8: ='Datos Históricos'!B7 -> 276 | D8: ='Datos Históricos'!E7 -> 275 | E8: ='Datos Históricos'!H7 -> 272 | F8: ='Datos Históricos'!K7 -> 280 | G8: ='Datos Históricos'!N7 -> 290 | H8: ='Datos Históricos'!Q7 -> 0 | I8: ='Datos Históricos'!T7 -> 0 | J8: ='Datos Históricos'!W7 -> 0 | K8: ='Datos Históricos'!Z7 -> 0 | L8: ='Datos Históricos'!AC7 -> 0 | M8: ='Datos Históricos'!AF7 -> 0 | N8: ='Datos Históricos'!AI7 -> 0 | O8: ='Datos Históricos'!C7 -> 18 | P8: ='Datos Históricos'!F7 -> 24 | Q8: ='Datos Históricos'!I7 -> 16 | R8: ='Datos Históricos'!L7 -> 13 | S8: ='Datos Históricos'!O7 -> 6 | T8: ='Datos Históricos'!R7 -> 0 | U8: ='Datos Históricos'!U7 -> 0 | V8: ='Datos Históricos'!X7 -> 0 | W8: ='Datos Históricos'!AA7 -> 0 | X8: ='Datos Históricos'!AD7 -> 0 | Y8: ='Datos Históricos'!AG7 -> 0 | Z8: ='Datos Históricos'!AJ7 -> 0
A9: ⬇ Cuando agregues un año nuevo en Hoja 1, extiende esta tabla hacia abajo con el periodo siguiente y referencias a esa fila
A11: SECCIÓN 1 – PROMEDIOS HISTÓRICOS POR MES
A12: Mes | B12: Prom.Ingresos | C12: Prom.Egresos | D12: Prom.Neto | E12: % Egreso/Ingreso | F12: Índice Estacionalidad | G12: Mín Ingresos | H12: Máx Ingresos
A13: ENE | B13: =IFERROR(AVERAGEIF(C6:C8,">0"),0) -> 381 | C13: =IFERROR(AVERAGEIF(O6:O8,">0"),0) -> 18.666667 | D13: =IFERROR(B13-C13,0) -> 362.33333 | E13: =IFERROR(C13/B13,0) -> 0.048993876 | F13: =IFERROR(B13/AVERAGE(B13:B24),0) -> 1.002192 | G13: =IFERROR(minifs(C6:C8,C6:C8,">0"),0) -> 0 | H13: =IFERROR(maxifs(C6:C8,C6:C8,">0"),0) -> 0
A14: FEB | B14: =IFERROR(AVERAGEIF(D6:D8,">0"),0) -> 387 | C14: =IFERROR(AVERAGEIF(P6:P8,">0"),0) -> 17.333333 | D14: =IFERROR(B14-C14,0) -> 369.66667 | E14: =IFERROR(C14/B14,0) -> 0.044788975 | F14: =IFERROR(B14/AVERAGE(B13:B24),0) -> 1.0179746 | G14: =IFERROR(minifs(D6:D8,D6:D8,">0"),0) -> 0 | H14: =IFERROR(maxifs(D6:D8,D6:D8,">0"),0) -> 0
A15: MAR | B15: =IFERROR(AVERAGEIF(E6:E8,">0"),0) -> 365 | C15: =IFERROR(AVERAGEIF(Q6:Q8,">0"),0) -> 23 | D15: =IFERROR(B15-C15,0) -> 342 | E15: =IFERROR(C15/B15,0) -> 0.063013699 | F15: =IFERROR(B15/AVERAGE(B13:B24),0) -> 0.96010522 | G15: =IFERROR(minifs(E6:E8,E6:E8,">0"),0) -> 0 | H15: =IFERROR(maxifs(E6:E8,E6:E8,">0"),0) -> 0
A16: ABR | B16: =IFERROR(AVERAGEIF(F6:F8,">0"),0) -> 357.33333 | C16: =IFERROR(AVERAGEIF(R6:R8,">0"),0) -> 15.666667 | D16: =IFERROR(B16-C16,0) -> 341.66667 | E16: =IFERROR(C16/B16,0) -> 0.043843284 | F16: =IFERROR(B16/AVERAGE(B13:B24),0) -> 0.93993862 | G16: =IFERROR(minifs(F6:F8,F6:F8,">0"),0) -> 0 | H16: =IFERROR(maxifs(F6:F8,F6:F8,">0"),0) -> 0
A17: MAY | B17: =IFERROR(AVERAGEIF(G6:G8,">0"),0) -> 366.66667 | C17: =IFERROR(AVERAGEIF(S6:S8,">0"),0) -> 18.666667 | D17: =IFERROR(B17-C17,0) -> 348 | E17: =IFERROR(C17/B17,0) -> 0.050909091 | F17: =IFERROR(B17/AVERAGE(B13:B24),0) -> 0.96448926 | G17: =IFERROR(minifs(G6:G8,G6:G8,">0"),0) -> 0 | H17: =IFERROR(maxifs(G6:G8,G6:G8,">0"),0) -> 0
A18: JUN | B18: =IFERROR(AVERAGEIF(H6:H8,">0"),0) -> 404.5 | C18: =IFERROR(AVERAGEIF(T6:T8,">0"),0) -> 20.5 | D18: =IFERROR(B18-C18,0) -> 384 | E18: =IFERROR(C18/B18,0) -> 0.050679852 | F18: =IFERROR(B18/AVERAGE(B13:B24),0) -> 1.064007 | G18: =IFERROR(minifs(H6:H8,H6:H8,">0"),0) -> 0 | H18: =IFERROR(maxifs(H6:H8,H6:H8,">0"),0) -> 0
A19: JUL | B19: =IFERROR(AVERAGEIF(I6:I8,">0"),0) -> 412.5 | C19: =IFERROR(AVERAGEIF(U6:U8,">0"),0) -> 29.5 | D19: =IFERROR(B19-C19,0) -> 383 | E19: =IFERROR(C19/B19,0) -> 0.071515152 | F19: =IFERROR(B19/AVERAGE(B13:B24),0) -> 1.0850504 | G19: =IFERROR(minifs(I6:I8,I6:I8,">0"),0) -> 0 | H19: =IFERROR(maxifs(I6:I8,I6:I8,">0"),0) -> 0
A20: AGO | B20: =IFERROR(AVERAGEIF(J6:J8,">0"),0) -> 405 | C20: =IFERROR(AVERAGEIF(V6:V8,">0"),0) -> 24 | D20: =IFERROR(B20-C20,0) -> 381 | E20: =IFERROR(C20/B20,0) -> 0.059259259 | F20: =IFERROR(B20/AVERAGE(B13:B24),0) -> 1.0653222 | G20: =IFERROR(minifs(J6:J8,J6:J8,">0"),0) -> 0 | H20: =IFERROR(maxifs(J6:J8,J6:J8,">0"),0) -> 0
A21: SEP | B21: =IFERROR(AVERAGEIF(K6:K8,">0"),0) -> 401.5 | C21: =IFERROR(AVERAGEIF(W6:W8,">0"),0) -> 37 | D21: =IFERROR(B21-C21,0) -> 364.5 | E21: =IFERROR(C21/B21,0) -> 0.092154421 | F21: =IFERROR(B21/AVERAGE(B13:B24),0) -> 1.0561157 | G21: =IFERROR(minifs(K6:K8,K6:K8,">0"),0) -> 0 | H21: =IFERROR(maxifs(K6:K8,K6:K8,">0"),0) -> 0
A22: OCT | B22: =IFERROR(AVERAGEIF(L6:L8,">0"),0) -> 383.5 | C22: =IFERROR(AVERAGEIF(X6:X8,">0"),0) -> 24.5 | D22: =IFERROR(B22-C22,0) -> 359 | E22: =IFERROR(C22/B22,0) -> 0.063885267 | F22: =IFERROR(B22/AVERAGE(B13:B24),0) -> 1.0087681 | G22: =IFERROR(minifs(L6:L8,L6:L8,">0"),0) -> 0 | H22: =IFERROR(maxifs(L6:L8,L6:L8,">0"),0) -> 0
A23: NOV | B23: =IFERROR(AVERAGEIF(M6:M8,">0"),0) -> 354 | C23: =IFERROR(AVERAGEIF(Y6:Y8,">0"),0) -> 23.5 | D23: =IFERROR(B23-C23,0) -> 330.5 | E23: =IFERROR(C23/B23,0) -> 0.066384181 | F23: =IFERROR(B23/AVERAGE(B13:B24),0) -> 0.93117054 | G23: =IFERROR(minifs(M6:M8,M6:M8,">0"),0) -> 0 | H23: =IFERROR(maxifs(M6:M8,M6:M8,">0"),0) -> 0
A24: DIC | B24: =IFERROR(AVERAGEIF(N6:N8,">0"),0) -> 344 | C24: =IFERROR(AVERAGEIF(Z6:Z8,">0"),0) -> 21.5 | D24: =IFERROR(B24-C24,0) -> 322.5 | E24: =IFERROR(C24/B24,0) -> 0.0625 | F24: =IFERROR(B24/AVERAGE(B13:B24),0) -> 0.90486629 | G24: =IFERROR(minifs(N6:N8,N6:N8,">0"),0) -> 0 | H24: =IFERROR(maxifs(N6:N8,N6:N8,">0"),0) -> 0
A27: SECCIÓN 2 – PARÁMETROS DE PREDICCIÓN (celdas en amarillo = editables)
A28: Año a predecir | B28: 2027 | C28: Cambia este valor al año que deseas estimar
A29: Factor ajuste tendencia | B29: 0 | C29: Ajuste manual sobre el forecast. Ej: -0.05 = 5% menos
A30: Multiplicador Pesimista | B30: 0.85 | C30: 0.85 = 15% menos que la predicción central
A31: Multiplicador Optimista | B31: 1.15 | C31: 1.15 = 15% más que la predicción central
A32: Confianza en el modelo (info) | B32: =IFERROR(RSQ(B6:B8,A6:A8),"N/D") -> 1 | C32: Basado en R² de la regresión — calculado automáticamente
A35: SECCIÓN 3 – PREDICCIÓN MENSUAL (FORECAST.LINEAR + ajustes)
A36: Mes | B36: Período Predicho | C36: FORECAST Ingresos (raw) | D36: Con Tendencia (Central Ing.) | E36: Pesimista Ingresos | F36: Optimista Ingresos | G36: FORECAST Egresos (raw) | H36: Egresos Central | I36: Neto Central | J36: Neto Pesimista | K36: Neto Optimista | L36: Variación vs prom histórico
A37: ENE | B37: =(B28-2024+1) -> 4 | C37: =IFERROR(forecast.linear(B37,C6:C8,A6:A8),B37*B13) -> 1524 | D37: =IFERROR(C37*(1+B29),"-") -> 1524 | E37: =IFERROR(D37*B30,"-") -> 1295.4 | F37: =IFERROR(D37*B31,"-") -> 1752.6 | G37: =IFERROR(forecast.linear(B37,O6:O8,A6:A8),B37*C13) -> 74.666667 | H37: =IFERROR(G37*(1+B29),"-") -> 74.666667 | I37: =IFERROR(D37-H37,"-") -> 1449.3333 | J37: =IFERROR(E37-H37,"-") -> 1220.7333 | K37: =IFERROR(F37-H37,"-") -> 1677.9333 | L37: =IFERROR((D37-B13)/B13,"-") -> 3
A38: FEB | B38: =(B28-2024+1) -> 4 | C38: =IFERROR(forecast.linear(B38,D6:D8,A6:A8),B38*B14) -> 1548 | D38: =IFERROR(C38*(1+B29),"-") -> 1548 | E38: =IFERROR(D38*B30,"-") -> 1315.8 | F38: =IFERROR(D38*B31,"-") -> 1780.2 | G38: =IFERROR(forecast.linear(B38,P6:P8,A6:A8),B38*C14) -> 69.333333 | H38: =IFERROR(G38*(1+B29),"-") -> 69.333333 | I38: =IFERROR(D38-H38,"-") -> 1478.6667 | J38: =IFERROR(E38-H38,"-") -> 1246.4667 | K38: =IFERROR(F38-H38,"-") -> 1710.8667 | L38: =IFERROR((D38-B14)/B14,"-") -> 3
A39: MAR | B39: =(B28-2024+1) -> 4 | C39: =IFERROR(forecast.linear(B39,E6:E8,A6:A8),B39*B15) -> 1460 | D39: =IFERROR(C39*(1+B29),"-") -> 1460 | E39: =IFERROR(D39*B30,"-") -> 1241 | F39: =IFERROR(D39*B31,"-") -> 1679 | G39: =IFERROR(forecast.linear(B39,Q6:Q8,A6:A8),B39*C15) -> 92 | H39: =IFERROR(G39*(1+B29),"-") -> 92 | I39: =IFERROR(D39-H39,"-") -> 1368 | J39: =IFERROR(E39-H39,"-") -> 1149 | K39: =IFERROR(F39-H39,"-") -> 1587 | L39: =IFERROR((D39-B15)/B15,"-") -> 3
A40: ABR | B40: =(B28-2024+1) -> 4 | C40: =IFERROR(forecast.linear(B40,F6:F8,A6:A8),B40*B16) -> 1429.3333 | D40: =IFERROR(C40*(1+B29),"-") -> 1429.3333 | E40: =IFERROR(D40*B30,"-") -> 1214.9333 | F40: =IFERROR(D40*B31,"-") -> 1643.7333 | G40: =IFERROR(forecast.linear(B40,R6:R8,A6:A8),B40*C16) -> 62.666667 | H40: =IFERROR(G40*(1+B29),"-") -> 62.666667 | I40: =IFERROR(D40-H40,"-") -> 1366.6667 | J40: =IFERROR(E40-H40,"-") -> 1152.2667 | K40: =IFERROR(F40-H40,"-") -> 1581.0667 | L40: =IFERROR((D40-B16)/B16,"-") -> 3
A41: MAY | B41: =(B28-2024+1) -> 4 | C41: =IFERROR(forecast.linear(B41,G6:G8,A6:A8),B41*B17) -> 1466.6667 | D41: =IFERROR(C41*(1+B29),"-") -> 1466.6667 | E41: =IFERROR(D41*B30,"-") -> 1246.6667 | F41: =IFERROR(D41*B31,"-") -> 1686.6667 | G41: =IFERROR(forecast.linear(B41,S6:S8,A6:A8),B41*C17) -> 74.666667 | H41: =IFERROR(G41*(1+B29),"-") -> 74.666667 | I41: =IFERROR(D41-H41,"-") -> 1392 | J41: =IFERROR(E41-H41,"-") -> 1172 | K41: =IFERROR(F41-H41,"-") -> 1612 | L41: =IFERROR((D41-B17)/B17,"-") -> 3
A42: JUN | B42: =(B28-2024+1) -> 4 | C42: =IFERROR(forecast.linear(B42,H6:H8,A6:A8),B42*B18) -> 1618 | D42: =IFERROR(C42*(1+B29),"-") -> 1618 | E42: =IFERROR(D42*B30,"-") -> 1375.3 | F42: =IFERROR(D42*B31,"-") -> 1860.7 | G42: =IFERROR(forecast.linear(B42,T6:T8,A6:A8),B42*C18) -> 82 | H42: =IFERROR(G42*(1+B29),"-") -> 82 | I42: =IFERROR(D42-H42,"-") -> 1536 | J42: =IFERROR(E42-H42,"-") -> 1293.3 | K42: =IFERROR(F42-H42,"-") -> 1778.7 | L42: =IFERROR((D42-B18)/B18,"-") -> 3
A43: JUL | B43: =(B28-2024+1) -> 4 | C43: =IFERROR(forecast.linear(B43,I6:I8,A6:A8),B43*B19) -> 1650 | D43: =IFERROR(C43*(1+B29),"-") -> 1650 | E43: =IFERROR(D43*B30,"-") -> 1402.5 | F43: =IFERROR(D43*B31,"-") -> 1897.5 | G43: =IFERROR(forecast.linear(B43,U6:U8,A6:A8),B43*C19) -> 118 | H43: =IFERROR(G43*(1+B29),"-") -> 118 | I43: =IFERROR(D43-H43,"-") -> 1532 | J43: =IFERROR(E43-H43,"-") -> 1284.5 | K43: =IFERROR(F43-H43,"-") -> 1779.5 | L43: =IFERROR((D43-B19)/B19,"-") -> 3
A44: AGO | B44: =(B28-2024+1) -> 4 | C44: =IFERROR(forecast.linear(B44,J6:J8,A6:A8),B44*B20) -> 1620 | D44: =IFERROR(C44*(1+B29),"-") -> 1620 | E44: =IFERROR(D44*B30,"-") -> 1377 | F44: =IFERROR(D44*B31,"-") -> 1863 | G44: =IFERROR(forecast.linear(B44,V6:V8,A6:A8),B44*C20) -> 96 | H44: =IFERROR(G44*(1+B29),"-") -> 96 | I44: =IFERROR(D44-H44,"-") -> 1524 | J44: =IFERROR(E44-H44,"-") -> 1281 | K44: =IFERROR(F44-H44,"-") -> 1767 | L44: =IFERROR((D44-B20)/B20,"-") -> 3
A45: SEP | B45: =(B28-2024+1) -> 4 | C45: =IFERROR(forecast.linear(B45,K6:K8,A6:A8),B45*B21) -> 1606 | D45: =IFERROR(C45*(1+B29),"-") -> 1606 | E45: =IFERROR(D45*B30,"-") -> 1365.1 | F45: =IFERROR(D45*B31,"-") -> 1846.9 | G45: =IFERROR(forecast.linear(B45,W6:W8,A6:A8),B45*C21) -> 148 | H45: =IFERROR(G45*(1+B29),"-") -> 148 | I45: =IFERROR(D45-H45,"-") -> 1458 | J45: =IFERROR(E45-H45,"-") -> 1217.1 | K45: =IFERROR(F45-H45,"-") -> 1698.9 | L45: =IFERROR((D45-B21)/B21,"-") -> 3
A46: OCT | B46: =(B28-2024+1) -> 4 | C46: =IFERROR(forecast.linear(B46,L6:L8,A6:A8),B46*B22) -> 1534 | D46: =IFERROR(C46*(1+B29),"-") -> 1534 | E46: =IFERROR(D46*B30,"-") -> 1303.9 | F46: =IFERROR(D46*B31,"-") -> 1764.1 | G46: =IFERROR(forecast.linear(B46,X6:X8,A6:A8),B46*C22) -> 98 | H46: =IFERROR(G46*(1+B29),"-") -> 98 | I46: =IFERROR(D46-H46,"-") -> 1436 | J46: =IFERROR(E46-H46,"-") -> 1205.9 | K46: =IFERROR(F46-H46,"-") -> 1666.1 | L46: =IFERROR((D46-B22)/B22,"-") -> 3
...

Sheet 📋 Instrucciones
A1: 📋 GUÍA DE USO DE LA PLANTILLA
A2: HOJA 1 — Datos Históricos
A3: • Col A = Año. Col B en adelante = Ingresos y Egresos por mes (pares).
A4: • Para agregar un nuevo mes con datos: llena Ingresos y Egresos en la columna correspondiente.
A5: • Para agregar un año nuevo: escribe el año en col A de la fila vacía y llena sus datos.
A6: • Las columnas 'Neto' y los Totales se calculan solos.
A8: HOJA 2 — Análisis & Predicción
A9: • Tabla auxiliar (arriba): vincula automáticamente los datos históricos para la regresión.
A10: Al agregar un año nuevo en Hoja 1, extiende esta tabla agregando una fila con el período siguiente.
A11: • SECCIÓN 1: Promedios e índices de estacionalidad por mes — se actualizan solos.
A12: • SECCIÓN 2: Cambia el 'Año a predecir' y los multiplicadores (celdas en AMARILLO).
A13: - Factor tendencia: 0 = sin ajuste manual. -0.05 = 5% a la baja.
... A29: Azul oscuro = Fórmulas calculadas (no editar)
